<robot
  name="/brazo_PF">

<link name="world"/>

  <joint name="fixed" type="fixed">
    <parent link="world"/>
    <child link="base_to_giro"/>
  </joint>

  <link
    name="base_to_giro">
    <inertial>
      <origin
        xyz="4.8481E-15 -1.6518E-13 0.0065907"
        rpy="0 0 0" />
      <mass
        value="0.26727" />
      <inertia
        ixx="0.0002228"
        ixy="-1.3665E-15"
        ixz="-3.2911E-09"
        iyy="0.0002228"
        iyz="-1.9001E-09"
        izz="0.00042782" />
    </inertial>
    <visual>
      <origin
        xyz="0 0 0"
        rpy="0 0 0" />
      <geometry>
        <mesh
          filename="package://brazo_PF/meshes/base_link.dae" />
      </geometry>
      <material
        name="">
        <color
          rgba="0.75294 0.75294 0.75294 1" />
      </material>
    </visual>
    <collision>
      <origin
        xyz="0.0001 0.0001 0.0001"
        rpy="0 0 0" />
      <geometry>
        <mesh
          filename="package://brazo_PF/meshes/base_link.dae" />
      </geometry>
    </collision>
  </link>
  <link
    name="link_giro">
    <inertial>
      <origin
        xyz="0.00096417 0.0016711 0.021724"
        rpy="0 0 0" />
      <mass
        value="0.26292" />
      <inertia
        ixx="0.0002813"
        ixy="3.324E-05"
        ixz="-1.4029E-05"
        iyy="0.00031973"
        iyz="-2.4312E-05"
        izz="0.00032314" />
    </inertial>
    <visual>
      <origin
        xyz="0 0 0"
        rpy="0 0 0" />
      <geometry>
        <mesh
          filename="package://brazo_PF/meshes/link_giro.dae" />
      </geometry>
      <material
        name="">
        <color
          rgba="0.75294 0.75294 0.75294 1" />
      </material>
    </visual>
    <collision>
      <origin
        xyz="0 0 0"
        rpy="0 0 0" />
      <geometry>
        <mesh
          filename="package://brazo_PF/meshes/link_giro.dae" />
      </geometry>
    </collision>
  </link>
  <joint name="Joint_giro" type="revolute">
    <origin
      xyz="0 0 0.022"
      rpy="-1.2292E-15 -1.1943E-15 7.3129E-32" />
    <parent
      link="base_to_giro" />
    <child
      link="link_giro" />
    <axis
      xyz="0 0 1" />
    <limit
      lower="-3.0"
      upper="3.0"
      effort="1"
      velocity="0.65" />
      <dynamics damping="0.7" />
  </joint>

  <link
    name="link_ante">
    <inertial>
      <origin
        xyz="-0.016633 0.027136 0.023335"
        rpy="0 0 0" />
      <mass
        value="0.055284" />
      <inertia
        ixx="6.8042E-05"
        ixy="2.9149E-05"
        ixz="-5.0246E-07"
        iyy="3.8057E-05"
        iyz="7.4452E-07"
        izz="7.1688E-05" />
    </inertial>
    <visual>
      <origin
        xyz="0 0 0"
        rpy="0 0 0" />
      <geometry>
        <mesh
          filename="package://brazo_PF/meshes/link_ante.dae" />
      </geometry>
      <material
        name="">
        <color
          rgba="0.49804 0.49804 0.49804 1" />
      </material>
    </visual>
    <collision>
      <origin
        xyz="0 0 0"
        rpy="0 0 0" />
      <geometry>
        <mesh
          filename="package://brazo_PF/meshes/link_ante.dae" />
      </geometry>
    </collision>
  </link>
  <joint
    name="Joint_Ante"
    type="revolute">
    <origin
      xyz="0.032369 0.0050749 0.060365"
      rpy="1.5708 4.1473E-16 -2.0941" />
    <parent
      link="link_giro" />
    <child
      link="link_ante" />
    <axis
      xyz="0 0 -1" />
    <limit
      lower="-1"
      upper="1"
      effort="1"
      velocity="0.3" />
      <dynamics damping="0.7" />
     
  </joint>
  <link
    name="Link_Cabe">
    <inertial>
      <origin
        xyz="-0.0049821 0.017822 0.020675"
        rpy="0 0 0" />
      <mass
        value="0.039731" />
      <inertia
        ixx="1.4781E-05"
        ixy="2.3994E-06"
        ixz="-3.5305E-12"
        iyy="2.4981E-05"
        iyz="-8.1746E-14"
        izz="1.8933E-05" />
    </inertial>
    <visual>
      <origin
        xyz="0 0 0"
        rpy="0 0 0" />
      <geometry>
        <mesh
          filename="package://brazo_PF/meshes/Link_Cabe.dae" />
      </geometry>
      <material
        name="">
        <color
          rgba="0.77647 0.75686 0.73725 1" />
      </material>
    </visual>
    <collision>
      <origin
        xyz="0 0 0"
        rpy="0 0 0" />
      <geometry>
        <mesh
          filename="package://brazo_PF/meshes/Link_Cabe.dae" />
      </geometry>
    </collision>
  </link>
  <joint
    name="Joint_Cabe"
    type="revolute">
    <origin
      xyz="-0.051814 0.08553 0.0435"
      rpy="-3.1416 1.0547E-15 -3.1416" />
    <parent
      link="link_ante" />
    <child
      link="Link_Cabe" />
    <axis
      xyz="0 0 1" />
    <limit
      lower="-1.57"
      upper="1.3"
      effort="1.1"
      velocity="0.65" />
      <!-- <dynamics damping="0.5" /> -->
  </joint>
  <link
    name="Link_giro_brazo">
    <inertial>
      <origin
        xyz="-0.00012055 0.00071169 0.097682"
        rpy="0 0 0" />
      <mass
        value="0.062038" />
      <inertia
        ixx="0.00011856"
        ixy="7.4607E-07"
        ixz="3.8551E-07"
        iyy="0.0001144"
        iyz="-2.2062E-06"
        izz="8.4168E-06" />
    </inertial>
    <visual>
      <origin
        xyz="0 0 0"
        rpy="0 0 0" />
      <geometry>
        <mesh
          filename="package://brazo_PF/meshes/Link_giro_brazo.dae" />
      </geometry>
      <material
        name="">
        <color
          rgba="0.75294 0.75294 0.75294 1" />
      </material>
    </visual>
    <collision>
      <origin
        xyz="0 0 0"
        rpy="0 0 0" />
      <geometry>
        <mesh
          filename="package://brazo_PF/meshes/Link_giro_brazo.dae" />
      </geometry>
    </collision>
  </link>
  <joint
    name="Joint_giro_brazo"
    type="revolute">
    <origin
      xyz="-0.0087752 0.019833 0.020675"
      rpy="0.20089 1.5708 0" />
    <parent
      link="Link_Cabe" />
    <child
      link="Link_giro_brazo" />
    <axis
      xyz="0 0 -1" />
    <limit
      lower="-3.0"
      upper="3.0"
      effort="0.1"
      velocity="0.1" />
      </joint>
  <link
    name="Link_muneca">
    <inertial>
      <origin
        xyz="2.3113E-06 -0.0096578 0.0092688"
        rpy="0 0 0" />
      <mass
        value="0.015068" />
      <inertia
        ixx="1.6097E-06"
        ixy="3.6664E-08"
        ixz="-7.1386E-11"
        iyy="2.602E-06"
        iyz="4.3518E-10"
        izz="2.3653E-06" />
    </inertial>
    <visual>
      <origin
        xyz="0 0 0"
        rpy="0 0 0" />
      <geometry>
        <mesh
          filename="package://brazo_PF/meshes/Link_muneca.dae" />
      </geometry>
      <material
        name="">
        <color
          rgba="0.75294 0.75294 0.75294 1" />
      </material>
    </visual>
    <collision>
      <origin
        xyz="0 0 0"
        rpy="0 0 0" />
      <geometry>
        <mesh
          filename="package://brazo_PF/meshes/Link_muneca.dae" />
      </geometry>
    </collision>
  </link>
  <joint
    name="Joint_muneca"
    type="revolute">
    <origin
      xyz="-0.0011973 0.0068867 0.15251"
      rpy="-1.5708 0.69932 -2.9695" />
    <parent
      link="Link_giro_brazo" />
    <child
      link="Link_muneca" />
    <axis
      xyz="0 0 -1" />
    <limit
      lower="-1.57"
      upper="1.57"
      effort="0.05"
      velocity="0.1" />
  </joint>
  <link
    name="Link_mano">
    <inertial>
      <origin
        xyz="-0.001097 0.00031683 0.00041728"
        rpy="0 0 0" />
      <mass
        value="0.00054683" />
      <inertia
        ixx="1.8792E-08"
        ixy="-2.214E-09"
        ixz="-2.916E-09"
        iyy="1.1766E-08"
        iyz="8.4217E-10"
        izz="1.2235E-08" />
    </inertial>
    <visual>
      <origin
        xyz="0 0 0"
        rpy="0 0 0" />
      <geometry>
        <mesh
          filename="package://brazo_PF/meshes/Link_mano.dae" />
      </geometry>
      <material
        name="">
        <color
          rgba="1 1 1 1" />
      </material>
    </visual>
    <collision>
      <origin
        xyz="0 0 0"
        rpy="0 0 0" />
      <geometry>
        <mesh
          filename="package://brazo_PF/meshes/Link_mano.dae" />
      </geometry>
    </collision>
  </link>
  <joint
    name="Joint_mano"
    type="revolute">
    <origin
      xyz="0.0045965 -0.02867 0.0093338"
      rpy="-1.4833 0.24918 -1.2291" />
    <parent
      link="Link_muneca" />
    <child
      link="Link_mano" />
    <axis
      xyz="0.90237 -0.26061 -0.34324" />
    <limit
      lower="-3.0"
      upper="3.0"
      effort="0.0001"
      velocity="0.01" />

  </joint>

<gazebo>
  <plugin name="gazebo_ros_control" filename="libgazebo_ros_control.so">
    <robotNamespace>/brazo_PF</robotNamespace>
      </plugin>
</gazebo>

  <transmission name="tran1">
    <type>transmission_interface/SimpleTransmission</type>
    <joint name="Joint_giro">
      <hardwareInterface>EffortJointInterface</hardwareInterface>
    </joint>
    <actuator name="motor1">
      <hardwareInterface>EffortJointInterface</hardwareInterface>
      <mechanicalReduction>1</mechanicalReduction>
    </actuator>
  </transmission>

  <transmission name="tran2">
    <type>transmission_interface/SimpleTransmission</type>
    <joint name="Joint_Ante">
      <hardwareInterface>EffortJointInterface</hardwareInterface>
    </joint>
    <actuator name="motor2">
      <hardwareInterface>EffortJointInterface</hardwareInterface>
      <mechanicalReduction>1</mechanicalReduction>
    </actuator>
  </transmission>

<transmission name="tran3">
    <type>transmission_interface/SimpleTransmission</type>
    <joint name="Joint_Cabe">
      <hardwareInterface>EffortJointInterface</hardwareInterface>
    </joint>
    <actuator name="motor3">
      <hardwareInterface>EffortJointInterface</hardwareInterface>
      <mechanicalReduction>1</mechanicalReduction>
    </actuator>
  </transmission>

  <transmission name="tran4">
    <type>transmission_interface/SimpleTransmission</type>
    <joint name="Joint_giro_brazo">
      <hardwareInterface>EffortJointInterface</hardwareInterface>
    </joint>
    <actuator name="motor4">
      <hardwareInterface>EffortJointInterface</hardwareInterface>
      <mechanicalReduction>1</mechanicalReduction>
    </actuator>
</transmission>

<transmission name="tran5">
    <type>transmission_interface/SimpleTransmission</type>
    <joint name="Joint_muneca">
      <hardwareInterface>EffortJointInterface</hardwareInterface>
    </joint>
    <actuator name="motor5">
      <hardwareInterface>EffortJointInterface</hardwareInterface>
      <mechanicalReduction>1</mechanicalReduction>
    </actuator>
  </transmission>

  <transmission name="tran6">
    <type>transmission_interface/SimpleTransmission</type>
    <joint name="Joint_mano">
      <hardwareInterface>EffortJointInterface</hardwareInterface>
    </joint>
    <actuator name="motor6">
      <hardwareInterface>EffortJointInterface</hardwareInterface>
      <mechanicalReduction>1</mechanicalReduction>
    </actuator>
</transmission>
</robot>